Workbook

Sheet Tabelle1
A1: Date | B1: Week | C1: Month | D1: Month_text | E1: Year | F1: Month_Year | G1: WeekDay | H1: Day_text | I1: WeekRunning | J1: Count | K1: Quarter | L1: UK_BH | M1: FR_BH | N1: SP_BH | O1: PT_BH | P1: WD_UK_Count | Q1: WD_FR_Count | R1: WD_SP_Count | S1: WD_PT_Count
A2: 42736 | B2: =WEEKNUM(A2) -> 1 | C2: =MONTH(A2) -> 1 | D2: =TEXT(A2,"mmmm") -> January | E2: =YEAR(A2) -> 2017 | F2: =CONCATENATE(calendar[[#This Row],[Month]],"/",calendar[[#This Row],[Year]]) -> 1/2017 | G2: =WEEKDAY(calendar[[#This Row],[Date]],1) -> 1 | H2: =TEXT(calendar[[#This Row],[WeekDay]],"dddd") -> Sunday | I2: 1 | J2: 0 | K2: =IF(calendar[[#This Row],[Month]]<4,1,IF(calendar[[#This Row],[Month]]<7,2,IF(calendar[[#This Row],[Month]]<10,3,4))) -> 1 | L2: =IFERROR(IF(VLOOKUP(calendar[[#This Row],[Date]],BH!A:A,1,)<>"",1,0),0) -> 0 | M2: =IFERROR(IF(VLOOKUP(calendar[[#This Row],[Date]],BH!C:C,1,)<>"",1,0),0) -> 0 | N2: =IFERROR(IF(VLOOKUP(calendar[[#This Row],[Date]],BH!E:E,1,)<>"",1,0),0) -> 0 | O2: =IFERROR(IF(VLOOKUP(calendar[[#This Row],[Date]],BH!G:G,1,)<>"",1,0),0) -> 0 | P2: 0 | Q2: 0 | R2: 0 | S2: 0
A3: 42737 | B3: =WEEKNUM(A3) -> 1 | C3: =MONTH(A3) -> 1 | D3: =TEXT(A3,"mmmm") -> January | E3: =YEAR(A3) -> 2017 | F3: =CONCATENATE(calendar[[#This Row],[Month]],"/",calendar[[#This Row],[Year]]) -> 1/2017 | G3: =WEEKDAY(calendar[[#This Row],[Date]],1) -> 2 | H3: =TEXT(calendar[[#This Row],[WeekDay]],"dddd") -> Monday | I3: =IF((INT(calendar[[#This Row],[Count]]/7)-calendar[[#This Row],[Count]]/7)<0,I2,I2+1) -> 1 | J3: =J2+1 -> 1 | K3: =IF(calendar[[#This Row],[Month]]<4,1,IF(calendar[[#This Row],[Month]]<7,2,IF(calendar[[#This Row],[Month]]<10,3,4))) -> 1 | L3: =IFERROR(IF(VLOOKUP(calendar[[#This Row],[Date]],BH!A:A,1,)<>"",1,0),0) -> 0 | M3: =IFERROR(IF(VLOOKUP(calendar[[#This Row],[Date]],BH!C:C,1,)<>"",1,0),0) -> 0 | N3: =IFERROR(IF(VLOOKUP(calendar[[#This Row],[Date]],BH!E:E,1,)<>"",1,0),0) -> 0 | O3: =IFERROR(IF(VLOOKUP(calendar[[#This Row],[Date]],BH!G:G,1,)<>"",1,0),0) -> 0 | P3: =IF(OR(calendar[[#This Row],[UK_BH]]=1,calendar[[#This Row],[WeekDay]]=1, calendar[[#This Row],[WeekDay]]=7),P2,P2+1) -> 1 | Q3: =IF(OR(calendar[[#This Row],[FR_BH]]=1,calendar[[#This Row],[WeekDay]]=1, calendar[[#This Row],[WeekDay]]=7),P2,P2+1) -> 1 | R3: =IF(OR(calendar[[#This Row],[SP_BH]]=1,calendar[[#This Row],[WeekDay]]=1, calendar[[#This Row],[WeekDay]]=7),P2,P2+1) -> 1 | S3: =IF(OR(calendar[[#This Row],[PT_BH]]=1,calendar[[#This Row],[WeekDay]]=1, calendar[[#This Row],[WeekDay]]=7),P2,P2+1) -> 1
A4: 42738 | B4: =WEEKNUM(A4) -> 1 | C4: =MONTH(A4) -> 1 | D4: =TEXT(A4,"mmmm") -> January | E4: =YEAR(A4) -> 2017 | F4: =CONCATENATE(calendar[[#This Row],[Month]],"/",calendar[[#This Row],[Year]]) -> 1/2017 | G4: =WEEKDAY(calendar[[#This Row],[Date]],1) -> 3 | H4: =TEXT(calendar[[#This Row],[WeekDay]],"dddd") -> Tuesday | I4: =IF((INT(calendar[[#This Row],[Count]]/7)-calendar[[#This Row],[Count]]/7)<0,I3,I3+1) -> 1 | J4: =J3+1 -> 2 | K4: =IF(calendar[[#This Row],[Month]]<4,1,IF(calendar[[#This Row],[Month]]<7,2,IF(calendar[[#This Row],[Month]]<10,3,4))) -> 1 | L4: =IFERROR(IF(VLOOKUP(calendar[[#This Row],[Date]],BH!A:A,1,)<>"",1,0),0) -> 0 | M4: =IFERROR(IF(VLOOKUP(calendar[[#This Row],[Date]],BH!C:C,1,)<>"",1,0),0) -> 0 | N4: =IFERROR(IF(VLOOKUP(calendar[[#This Row],[Date]],BH!E:E,1,)<>"",1,0),0) -> 0 | O4: =IFERROR(IF(VLOOKUP(calendar[[#This Row],[Date]],BH!G:G,1,)<>"",1,0),0) -> 0 | P4: =IF(OR(calendar[[#This Row],[UK_BH]]=1,calendar[[#This Row],[WeekDay]]=1, calendar[[#This Row],[WeekDay]]=7),P3,P3+1) -> 2 | Q4: =IF(OR(calendar[[#This Row],[FR_BH]]=1,calendar[[#This Row],[WeekDay]]=1, calendar[[#This Row],[WeekDay]]=7),P3,P3+1) -> 2 | R4: =IF(OR(calendar[[#This Row],[SP_BH]]=1,calendar[[#This Row],[WeekDay]]=1, calendar[[#This Row],[WeekDay]]=7),P3,P3+1) -> 2 | S4: =IF(OR(calendar[[#This Row],[PT_BH]]=1,calendar[[#This Row],[WeekDay]]=1, calendar[[#This Row],[WeekDay]]=7),P3,P3+1) -> 2
A5: 42739 | B5: =WEEKNUM(A5) -> 1 | C5: =MONTH(A5) -> 1 | D5: =TEXT(A5,"mmmm") -> January | E5: =YEAR(A5) -> 2017 | F5: =CONCATENATE(calendar[[#This Row],[Month]],"/",calendar[[#This Row],[Year]]) -> 1/2017 | G5: =WEEKDAY(calendar[[#This Row],[Date]],1) -> 4 | H5: =TEXT(calendar[[#This Row],[WeekDay]],"dddd") -> Wednesday | I5: =IF((INT(calendar[[#This Row],[Count]]/7)-calendar[[#This Row],[Count]]/7)<0,I4,I4+1) -> 1 | J5: =J4+1 -> 3 | K5: =IF(calendar[[#This Row],[Month]]<4,1,IF(calendar[[#This Row],[Month]]<7,2,IF(calendar[[#This Row],[Month]]<10,3,4))) -> 1 | L5: =IFERROR(IF(VLOOKUP(calendar[[#This Row],[Date]],BH!A:A,1,)<>"",1,0),0) -> 0 | M5: =IFERROR(IF(VLOOKUP(calendar[[#This Row],[Date]],BH!C:C,1,)<>"",1,0),0) -> 0 | N5: =IFERROR(IF(VLOOKUP(calendar[[#This Row],[Date]],BH!E:E,1,)<>"",1,0),0) -> 0 | O5: =IFERROR(IF(VLOOKUP(calendar[[#This Row],[Date]],BH!G:G,1,)<>"",1,0),0) -> 0 | P5: =IF(OR(calendar[[#This Row],[UK_BH]]=1,calendar[[#This Row],[WeekDay]]=1, calendar[[#This Row],[WeekDay]]=7),P4,P4+1) -> 3 | Q5: =IF(OR(calendar[[#This Row],[FR_BH]]=1,calendar[[#This Row],[WeekDay]]=1, calendar[[#This Row],[WeekDay]]=7),P4,P4+1) -> 3 | R5: =IF(OR(calendar[[#This Row],[SP_BH]]=1,calendar[[#This Row],[WeekDay]]=1, calendar[[#This Row],[WeekDay]]=7),P4,P4+1) -> 3 | S5: =IF(OR(calendar[[#This Row],[PT_BH]]=1,calendar[[#This Row],[WeekDay]]=1, calendar[[#This Row],[WeekDay]]=7),P4,P4+1) -> 3
A6: 42740 | B6: =WEEKNUM(A6) -> 1 | C6: =MONTH(A6) -> 1 | D6: =TEXT(A6,"mmmm") -> January | E6: =YEAR(A6) -> 2017 | F6: =CONCATENATE(calendar[[#This Row],[Month]],"/",calendar[[#This Row],[Year]]) -> 1/2017 | G6: =WEEKDAY(calendar[[#This Row],[Date]],1) -> 5 | H6: =TEXT(calendar[[#This Row],[WeekDay]],"dddd") -> Thursday | I6: =IF((INT(calendar[[#This Row],[Count]]/7)-calendar[[#This Row],[Count]]/7)<0,I5,I5+1) -> 1 | J6: =J5+1 -> 4 | K6: =IF(calendar[[#This Row],[Month]]<4,1,IF(calendar[[#This Row],[Month]]<7,2,IF(calendar[[#This Row],[Month]]<10,3,4))) -> 1 | L6: =IFERROR(IF(VLOOKUP(calendar[[#This Row],[Date]],BH!A:A,1,)<>"",1,0),0) -> 0 | M6: =IFERROR(IF(VLOOKUP(calendar[[#This Row],[Date]],BH!C:C,1,)<>"",1,0),0) -> 0 | N6: =IFERROR(IF(VLOOKUP(calendar[[#This Row],[Date]],BH!E:E,1,)<>"",1,0),0) -> 0 | O6: =IFERROR(IF(VLOOKUP(calendar[[#This Row],[Date]],BH!G:G,1,)<>"",1,0),0) -> 0 | P6: =IF(OR(calendar[[#This Row],[UK_BH]]=1,calendar[[#This Row],[WeekDay]]=1, calendar[[#This Row],[WeekDay]]=7),P5,P5+1) -> 4 | Q6: =IF(OR(calendar[[#This Row],[FR_BH]]=1,calendar[[#This Row],[WeekDay]]=1, calendar[[#This Row],[WeekDay]]=7),P5,P5+1) -> 4 | R6: =IF(OR(calendar[[#This Row],[SP_BH]]=1,calendar[[#This Row],[WeekDay]]=1, calendar[[#This Row],[WeekDay]]=7),P5,P5+1) -> 4 | S6: =IF(OR(calendar[[#This Row],[PT_BH]]=1,calendar[[#This Row],[WeekDay]]=1, calendar[[#This Row],[WeekDay]]=7),P5,P5+1) -> 4
A7: 42741 | B7: =WEEKNUM(A7) -> 1 | C7: =MONTH(A7) -> 1 | D7: =TEXT(A7,"mmmm") -> January | E7: =YEAR(A7) -> 2017 | F7: =CONCATENATE(calendar[[#This Row],[Month]],"/",calendar[[#This Row],[Year]]) -> 1/2017 | G7: =WEEKDAY(calendar[[#This Row],[Date]],1) -> 6 | H7: =TEXT(calendar[[#This Row],[WeekDay]],"dddd") -> Friday | I7: =IF((INT(calendar[[#This Row],[Count]]/7)-calendar[[#This Row],[Count]]/7)<0,I6,I6+1) -> 1 | J7: =J6+1 -> 5 | K7: =IF(calendar[[#This Row],[Month]]<4,1,IF(calendar[[#This Row],[Month]]<7,2,IF(calendar[[#This Row],[Month]]<10,3,4))) -> 1 | L7: =IFERROR(IF(VLOOKUP(calendar[[#This Row],[Date]],BH!A:A,1,)<>"",1,0),0) -> 0 | M7: =IFERROR(IF(VLOOKUP(calendar[[#This Row],[Date]],BH!C:C,1,)<>"",1,0),0) -> 0 | N7: =IFERROR(IF(VLOOKUP(calendar[[#This Row],[Date]],BH!E:E,1,)<>"",1,0),0) -> 0 | O7: =IFERROR(IF(VLOOKUP(calendar[[#This Row],[Date]],BH!G:G,1,)<>"",1,0),0) -> 0 | P7: =IF(OR(calendar[[#This Row],[UK_BH]]=1,calendar[[#This Row],[WeekDay]]=1, calendar[[#This Row],[WeekDay]]=7),P6,P6+1) -> 5 | Q7: =IF(OR(calendar[[#This Row],[FR_BH]]=1,calendar[[#This Row],[WeekDay]]=1, calendar[[#This Row],[WeekDay]]=7),P6,P6+1) -> 5 | R7: =IF(OR(calendar[[#This Row],[SP_BH]]=1,calendar[[#This Row],[WeekDay]]=1, calendar[[#This Row],[WeekDay]]=7),P6,P6+1) -> 5 | S7: =IF(OR(calendar[[#This Row],[PT_BH]]=1,calendar[[#This Row],[WeekDay]]=1, calendar[[#This Row],[WeekDay]]=7),P6,P6+1) -> 5
A8: 42742 | B8: =WEEKNUM(A8) -> 1 | C8: =MONTH(A8) -> 1 | D8: =TEXT(A8,"mmmm") -> January | E8: =YEAR(A8) -> 2017 | F8: =CONCATENATE(calendar[[#This Row],[Month]],"/",calendar[[#This Row],[Year]]) -> 1/2017 | G8: =WEEKDAY(calendar[[#This Row],[Date]],1) -> 7 | H8: =TEXT(calendar[[#This Row],[WeekDay]],"dddd") -> Saturday | I8: =IF((INT(calendar[[#This Row],[Count]]/7)-calendar[[#This Row],[Count]]/7)<0,I7,I7+1) -> 1 | J8: =J7+1 -> 6 | K8: =IF(calendar[[#This Row],[Month]]<4,1,IF(calendar[[#This Row],[Month]]<7,2,IF(calendar[[#This Row],[Month]]<10,3,4))) -> 1 | L8: =IFERROR(IF(VLOOKUP(calendar[[#This Row],[Date]],BH!A:A,1,)<>"",1,0),0) -> 0 | M8: =IFERROR(IF(VLOOKUP(calendar[[#This Row],[Date]],BH!C:C,1,)<>"",1,0),0) -> 0 | N8: =IFERROR(IF(VLOOKUP(calendar[[#This Row],[Date]],BH!E:E,1,)<>"",1,0),0) -> 0 | O8: =IFERROR(IF(VLOOKUP(calendar[[#This Row],[Date]],BH!G:G,1,)<>"",1,0),0) -> 0 | P8: =IF(OR(calendar[[#This Row],[UK_BH]]=1,calendar[[#This Row],[WeekDay]]=1, calendar[[#This Row],[WeekDay]]=7),P7,P7+1) -> 5 | Q8: =IF(OR(calendar[[#This Row],[FR_BH]]=1,calendar[[#This Row],[WeekDay]]=1, calendar[[#This Row],[WeekDay]]=7),P7,P7+1) -> 5 | R8: =IF(OR(calendar[[#This Row],[SP_BH]]=1,calendar[[#This Row],[WeekDay]]=1, calendar[[#This Row],[WeekDay]]=7),P7,P7+1) -> 5 | S8: =IF(OR(calendar[[#This Row],[PT_BH]]=1,calendar[[#This Row],[WeekDay]]=1, calendar[[#This Row],[WeekDay]]=7),P7,P7+1) -> 5
A9: 42743 | B9: =WEEKNUM(A9) -> 2 | C9: =MONTH(A9) -> 1 | D9: =TEXT(A9,"mmmm") -> January | E9: =YEAR(A9) -> 2017 | F9: =CONCATENATE(calendar[[#This Row],[Month]],"/",calendar[[#This Row],[Year]]) -> 1/2017 | G9: =WEEKDAY(calendar[[#This Row],[Date]],1) -> 1 | H9: =TEXT(calendar[[#This Row],[WeekDay]],"dddd") -> Sunday | I9: =IF((INT(calendar[[#This Row],[Count]]/7)-calendar[[#This Row],[Count]]/7)<0,I8,I8+1) -> 2 | J9: =J8+1 -> 7 | K9: =IF(calendar[[#This Row],[Month]]<4,1,IF(calendar[[#This Row],[Month]]<7,2,IF(calendar[[#This Row],[Month]]<10,3,4))) -> 1 | L9: =IFERROR(IF(VLOOKUP(calendar[[#This Row],[Date]],BH!A:A,1,)<>"",1,0),0) -> 0 | M9: =IFERROR(IF(VLOOKUP(calendar[[#This Row],[Date]],BH!C:C,1,)<>"",1,0),0) -> 0 | N9: =IFERROR(IF(VLOOKUP(calendar[[#This Row],[Date]],BH!E:E,1,)<>"",1,0),0) -> 0 | O9: =IFERROR(IF(VLOOKUP(calendar[[#This Row],[Date]],BH!G:G,1,)<>"",1,0),0) -> 0 | P9: =IF(OR(calendar[[#This Row],[UK_BH]]=1,calendar[[#This Row],[WeekDay]]=1, calendar[[#This Row],[WeekDay]]=7),P8,P8+1) -> 5 | Q9: =IF(OR(calendar[[#This Row],[FR_BH]]=1,calendar[[#This Row],[WeekDay]]=1, calendar[[#This Row],[WeekDay]]=7),P8,P8+1) -> 5 | R9: =IF(OR(calendar[[#This Row],[SP_BH]]=1,calendar[[#This Row],[WeekDay]]=1, calendar[[#This Row],[WeekDay]]=7),P8,P8+1) -> 5 | S9: =IF(OR(calendar[[#This Row],[PT_BH]]=1,calendar[[#This Row],[WeekDay]]=1, calendar[[#This Row],[WeekDay]]=7),P8,P8+1) -> 5
A10: 42744 | B10: =WEEKNUM(A10) -> 2 | C10: =MONTH(A10) -> 1 | D10: =TEXT(A10,"mmmm") -> January | E10: =YEAR(A10) -> 2017 | F10: =CONCATENATE(calendar[[#This Row],[Month]],"/",calendar[[#This Row],[Year]]) -> 1/2017 | G10: =WEEKDAY(calendar[[#This Row],[Date]],1) -> 2 | H10: =TEXT(calendar[[#This Row],[WeekDay]],"dddd") -> Monday | I10: =IF((INT(calendar[[#This Row],[Count]]/7)-calendar[[#This Row],[Count]]/7)<0,I9,I9+1) -> 2 | J10: =J9+1 -> 8 | K10: =IF(calendar[[#This Row],[Month]]<4,1,IF(calendar[[#This Row],[Month]]<7,2,IF(calendar[[#This Row],[Month]]<10,3,4))) -> 1 | L10: =IFERROR(IF(VLOOKUP(calendar[[#This Row],[Date]],BH!A:A,1,)<>"",1,0),0) -> 0 | M10: =IFERROR(IF(VLOOKUP(calendar[[#This Row],[Date]],BH!C:C,1,)<>"",1,0),0) -> 0 | N10: =IFERROR(IF(VLOOKUP(calendar[[#This Row],[Date]],BH!E:E,1,)<>"",1,0),0) -> 0 | O10: =IFERROR(IF(VLOOKUP(calendar[[#This Row],[Date]],BH!G:G,1,)<>"",1,0),0) -> 0 | P10: =IF(OR(calendar[[#This Row],[UK_BH]]=1,calendar[[#This Row],[WeekDay]]=1, calendar[[#This Row],[WeekDay]]=7),P9,P9+1) -> 6 | Q10: =IF(OR(calendar[[#This Row],[FR_BH]]=1,calendar[[#This Row],[WeekDay]]=1, calendar[[#This Row],[WeekDay]]=7),P9,P9+1) -> 6 | R10: =IF(OR(calendar[[#This Row],[SP_BH]]=1,calendar[[#This Row],[WeekDay]]=1, calendar[[#This Row],[WeekDay]]=7),P9,P9+1) -> 6 | S10: =IF(OR(calendar[[#This Row],[PT_BH]]=1,calendar[[#This Row],[WeekDay]]=1, calendar[[#This Row],[WeekDay]]=7),P9,P9+1) -> 6
A11: 42745 | B11: =WEEKNUM(A11) -> 2 | C11: =MONTH(A11) -> 1 | D11: =TEXT(A11,"mmmm") -> January | E11: =YEAR(A11) -> 2017 | F11: =CONCATENATE(calendar[[#This Row],[Month]],"/",calendar[[#This Row],[Year]]) -> 1/2017 | G11: =WEEKDAY(calendar[[#This Row],[Date]],1) -> 3 | H11: =TEXT(calendar[[#This Row],[WeekDay]],"dddd") -> Tuesday | I11: =IF((INT(calendar[[#This Row],[Count]]/7)-calendar[[#This Row],[Count]]/7)<0,I10,I10+1) -> 2 | J11: =J10+1 -> 9 | K11: =IF(calendar[[#This Row],[Month]]<4,1,IF(calendar[[#This Row],[Month]]<7,2,IF(calendar[[#This Row],[Month]]<10,3,4))) -> 1 | L11: =IFERROR(IF(VLOOKUP(calendar[[#This Row],[Date]],BH!A:A,1,)<>"",1,0),0) -> 0 | M11: =IFERROR(IF(VLOOKUP(calendar[[#This Row],[Date]],BH!C:C,1,)<>"",1,0),0) -> 0 | N11: =IFERROR(IF(VLOOKUP(calendar[[#This Row],[Date]],BH!E:E,1,)<>"",1,0),0) -> 0 | O11: =IFERROR(IF(VLOOKUP(calendar[[#This Row],[Date]],BH!G:G,1,)<>"",1,0),0) -> 0 | P11: =IF(OR(calendar[[#This Row],[UK_BH]]=1,calendar[[#This Row],[WeekDay]]=1, calendar[[#This Row],[WeekDay]]=7),P10,P10+1) -> 7 | Q11: =IF(OR(calendar[[#This Row],[FR_BH]]=1,calendar[[#This Row],[WeekDay]]=1, calendar[[#This Row],[WeekDay]]=7),P10,P10+1) -> 7 | R11: =IF(OR(calendar[[#This Row],[SP_BH]]=1,calendar[[#This Row],[WeekDay]]=1, calendar[[#This Row],[WeekDay]]=7),P10,P10+1) -> 7 | S11: =IF(OR(calendar[[#This Row],[PT_BH]]=1,calendar[[#This Row],[WeekDay]]=1, calendar[[#This Row],[WeekDay]]=7),P10,P10+1) -> 7
A12: 42746 | B12: =WEEKNUM(A12) -> 2 | C12: =MONTH(A12) -> 1 | D12: =TEXT(A12,"mmmm") -> January | E12: =YEAR(A12) -> 2017 | F12: =CONCATENATE(calendar[[#This Row],[Month]],"/",calendar[[#This Row],[Year]]) -> 1/2017 | G12: =WEEKDAY(calendar[[#This Row],[Date]],1) -> 4 | H12: =TEXT(calendar[[#This Row],[WeekDay]],"dddd") -> Wednesday | I12: =IF((INT(calendar[[#This Row],[Count]]/7)-calendar[[#This Row],[Count]]/7)<0,I11,I11+1) -> 2 | J12: =J11+1 -> 10 | K12: =IF(calendar[[#This Row],[Month]]<4,1,IF(calendar[[#This Row],[Month]]<7,2,IF(calendar[[#This Row],[Month]]<10,3,4))) -> 1 | L12: =IFERROR(IF(VLOOKUP(calendar[[#This Row],[Date]],BH!A:A,1,)<>"",1,0),0) -> 0 | M12: =IFERROR(IF(VLOOKUP(calendar[[#This Row],[Date]],BH!C:C,1,)<>"",1,0),0) -> 0 | N12: =IFERROR(IF(VLOOKUP(calendar[[#This Row],[Date]],BH!E:E,1,)<>"",1,0),0) -> 0 | O12: =IFERROR(IF(VLOOKUP(calendar[[#This Row],[Date]],BH!G:G,1,)<>"",1,0),0) -> 0 | P12: =IF(OR(calendar[[#This Row],[UK_BH]]=1,calendar[[#This Row],[WeekDay]]=1, calendar[[#This Row],[WeekDay]]=7),P11,P11+1) -> 8 | Q12: =IF(OR(calendar[[#This Row],[FR_BH]]=1,calendar[[#This Row],[WeekDay]]=1, calendar[[#This Row],[WeekDay]]=7),P11,P11+1) -> 8 | R12: =IF(OR(calendar[[#This Row],[SP_BH]]=1,calendar[[#This Row],[WeekDay]]=1, calendar[[#This Row],[WeekDay]]=7),P11,P11+1) -> 8 | S12: =IF(OR(calendar[[#This Row],[PT_BH]]=1,calendar[[#This Row],[WeekDay]]=1, calendar[[#This Row],[WeekDay]]=7),P11,P11+1) -> 8
A13: 42747 | B13: =WEEKNUM(A13) -> 2 | C13: =MONTH(A13) -> 1 | D13: =TEXT(A13,"mmmm") -> January | E13: =YEAR(A13) -> 2017 | F13: =CONCATENATE(calendar[[#This Row],[Month]],"/",calendar[[#This Row],[Year]]) -> 1/2017 | G13: =WEEKDAY(calendar[[#This Row],[Date]],1) -> 5 | H13: =TEXT(calendar[[#This Row],[WeekDay]],"dddd") -> Thursday | I13: =IF((INT(calendar[[#This Row],[Count]]/7)-calendar[[#This Row],[Count]]/7)<0,I12,I12+1) -> 2 | J13: =J12+1 -> 11 | K13: =IF(calendar[[#This Row],[Month]]<4,1,IF(calendar[[#This Row],[Month]]<7,2,IF(calendar[[#This Row],[Month]]<10,3,4))) -> 1 | L13: =IFERROR(IF(VLOOKUP(calendar[[#This Row],[Date]],BH!A:A,1,)<>"",1,0),0) -> 0 | M13: =IFERROR(IF(VLOOKUP(calendar[[#This Row],[Date]],BH!C:C,1,)<>"",1,0),0) -> 0 | N13: =IFERROR(IF(VLOOKUP(calendar[[#This Row],[Date]],BH!E:E,1,)<>"",1,0),0) -> 0 | O13: =IFERROR(IF(VLOOKUP(calendar[[#This Row],[Date]],BH!G:G,1,)<>"",1,0),0) -> 0 | P13: =IF(OR(calendar[[#This Row],[UK_BH]]=1,calendar[[#This Row],[WeekDay]]=1, calendar[[#This Row],[WeekDay]]=7),P12,P12+1) -> 9 | Q13: =IF(OR(calendar[[#This Row],[FR_BH]]=1,calendar[[#This Row],[WeekDay]]=1, calendar[[#This Row],[WeekDay]]=7),P12,P12+1) -> 9 | R13: =IF(OR(calendar[[#This Row],[SP_BH]]=1,calendar[[#This Row],[WeekDay]]=1, calendar[[#This Row],[WeekDay]]=7),P12,P12+1) -> 9 | S13: =IF(OR(calendar[[#This Row],[PT_BH]]=1,calendar[[#This Row],[WeekDay]]=1, calendar[[#This Row],[WeekDay]]=7),P12,P12+1) -> 9
A14: 42748 | B14: =WEEKNUM(A14) -> 2 | C14: =MONTH(A14) -> 1 | D14: =TEXT(A14,"mmmm") -> January | E14: =YEAR(A14) -> 2017 | F14: =CONCATENATE(calendar[[#This Row],[Month]],"/",calendar[[#This Row],[Year]]) -> 1/2017 | G14: =WEEKDAY(calendar[[#This Row],[Date]],1) -> 6 | H14: =TEXT(calendar[[#This Row],[WeekDay]],"dddd") -> Friday | I14: =IF((INT(calendar[[#This Row],[Count]]/7)-calendar[[#This Row],[Count]]/7)<0,I13,I13+1) -> 2 | J14: =J13+1 -> 12 | K14: =IF(calendar[[#This Row],[Month]]<4,1,IF(calendar[[#This Row],[Month]]<7,2,IF(calendar[[#This Row],[Month]]<10,3,4))) -> 1 | L14: =IFERROR(IF(VLOOKUP(calendar[[#This Row],[Date]],BH!A:A,1,)<>"",1,0),0) -> 0 | M14: =IFERROR(IF(VLOOKUP(calendar[[#This Row],[Date]],BH!C:C,1,)<>"",1,0),0) -> 0 | N14: =IFERROR(IF(VLOOKUP(calendar[[#This Row],[Date]],BH!E:E,1,)<>"",1,0),0) -> 0 | O14: =IFERROR(IF(VLOOKUP(calendar[[#This Row],[Date]],BH!G:G,1,)<>"",1,0),0) -> 0 | P14: =IF(OR(calendar[[#This Row],[UK_BH]]=1,calendar[[#This Row],[WeekDay]]=1, calendar[[#This Row],[WeekDay]]=7),P13,P13+1) -> 10 | Q14: =IF(OR(calendar[[#This Row],[FR_BH]]=1,calendar[[#This Row],[WeekDay]]=1, calendar[[#This Row],[WeekDay]]=7),P13,P13+1) -> 10 | R14: =IF(OR(calendar[[#This Row],[SP_BH]]=1,calendar[[#This Row],[WeekDay]]=1, calendar[[#This Row],[WeekDay]]=7),P13,P13+1) -> 10 | S14: =IF(OR(calendar[[#This Row],[PT_BH]]=1,calendar[[#This Row],[WeekDay]]=1, calendar[[#This Row],[WeekDay]]=7),P13,P13+1) -> 10
... A4384: 47118 | B4384: =WEEKNUM(A4384) -> 54 | C4384: =MONTH(A4384) -> 12 | D4384: =TEXT(A4384,"mmmm") -> December | E4384: =YEAR(A4384) -> 2028 | F4384: =CONCATENATE(calendar[[#This Row],[Month]],"/",calendar[[#This Row],[Year]]) -> 12/2028 | G4384: =WEEKDAY(calendar[[#This Row],[Date]],1) -> 1 | H4384: =TEXT(calendar[[#This Row],[WeekDay]],"dddd") -> Sunday | I4384: =IF((INT(calendar[[#This Row],[Count]]/7)-calendar[[#This Row],[Count]]/7)<0,I4383,I4383+1) -> 627 | J4384: =J4383+1 -> 4382 | K4384: =IF(calendar[[#This Row],[Month]]<4,1,IF(calendar[[#This Row],[Month]]<7,2,IF(calendar[[#This Row],[Month]]<10,3,4))) -> 4 | L4384: =IFERROR(IF(VLOOKUP(calendar[[#This Row],[Date]],BH!A:A,1,)<>"",1,0),0) -> 0 | M4384: =IFERROR(IF(VLOOKUP(calendar[[#This Row],[Date]],BH!C:C,1,)<>"",1,0),0) -> 0 | N4384: =IFERROR(IF(VLOOKUP(calendar[[#This Row],[Date]],BH!E:E,1,)<>"",1,0),0) -> 0 | O4384: =IFERROR(IF(VLOOKUP(calendar[[#This Row],[Date]],BH!G:G,1,)<>"",1,0),0) -> 0 | P4384: =IF(OR(calendar[[#This Row],[UK_BH]]=1,calendar[[#This Row],[WeekDay]]=1, calendar[[#This Row],[WeekDay]]=7),P4383,P4383+1) -> 3106 | Q4384: =IF(OR(calendar[[#This Row],[FR_BH]]=1,calendar[[#This Row],[WeekDay]]=1, calendar[[#This Row],[WeekDay]]=7),P4383,P4383+1) -> 3106 | R4384: =IF(OR(calendar[[#This Row],[SP_BH]]=1,calendar[[#This Row],[WeekDay]]=1, calendar[[#This Row],[WeekDay]]=7),P4383,P4383+1) -> 3106 | S4384: =IF(OR(calendar[[#This Row],[PT_BH]]=1,calendar[[#This Row],[WeekDay]]=1, calendar[[#This Row],[WeekDay]]=7),P4383,P4383+1) -> 3106

Sheet BH
A1: UK | C1: FRA | E1: ES | G1: PT
A2: 45658 | C2: 45658 | E2: 45658 | G2: 45658
A3: 45765 | C3: 45765 | E3: 45663 | G3: 45765
A4: 45768 | C4: 45768 | E4: 45717 | G4: 45767
A5: 45782 | C5: 45778 | E5: 45735 | G5: 45772
A6: 45803 | C6: 45785 | E6: 45760 | G6: 45778
A7: 45894 | C7: 45806 | E7: 45764 | G7: 45818
A8: 46016 | C8: 45816 | E8: 45765 | G8: 45827
A9: 46017 | C9: 45817 | E9: 45767 | G9: 45884
A10: 46023 | C10: 45852 | E10: 45775 | G10: 45935
A11: 46115 | C11: 45884 | E11: 45778 | G11: 45962
A12: 46118 | C12: 45962 | E12: 45779 | G12: 45992
A13: 46146 | C13: 45972 | E13: 45781 | G13: 45999
... A25: 46749 | C25: 46249 | E25: 46017 | G25: 46357
C26: 46327 | E26: 46023 | G26: 46364
C27: 46337 | E27: 46028 | G27: 46381
C28: 46381 | E28: 46082 | G28: 46388
C29: 46382 | E29: 46100 | G29: 46472
C30: 46388 | E30: 46110 | G30: 46474
C31: 46472 | E31: 46114 | G31: 46502
C32: 46475 | E32: 46115 | G32: 46508
C33: 46539 | E33: 46117 | G33: 46534
C34: 46513 | E34: 46118 | G34: 46548
C35: 46515 | E35: 46140 | G35: 46614
C36: 46523 | E36: 46143 | G36: 46665
C37: 46524 | E37: 46144 | G37: 46692
... C40: 46692 | E40: 46166 | G40: 46746
C41: 46702 | E41: 46172
C42: 46746 | E42: 46197
C43: 46747 | E43: 46249
E44: 46304
E45: 46307
E46: 46327
E47: 46328
E48: 46362
E49: 46364
E50: 46381
E51: 46382
E52: 46388
E53: 46393
...
